<?xml version="1.0"?>
<robot xmlns:xacro="http://www.ros.org/wiki/xacro">

  <xacro:macro name="inner_knuckle" params="prefix finger_prefix mirror:=1">

    <xacro:property name="open" value="2.33525" />
    <xacro:property name="close" value="1.42244" />

    <joint name="${prefix}${finger_prefix}inner_knuckle_joint" type="revolute">
      <origin xyz="0 ${mirror * 0.016} 0.10586" rpy="${pi/2} 0 ${mirror * -pi/2}" />
      <parent link="${prefix}base_link" />
      <child link="${prefix}${finger_prefix}inner_knuckle" />
      <axis xyz="0 0 1" />
      <limit lower="${close}" upper="${open}" velocity="1.0"  effort="90.0" />
      <mimic joint="${prefix}finger_joint" offset="${close}" multiplier="${(close - open) / 0.03}" />
    </joint>

    <link name="${prefix}${finger_prefix}inner_knuckle">
      <visual>
        <origin xyz="0 0 0" rpy="0 0 0" />
        <geometry>
          <mesh filename="package://dh_description/meshes/ag95/inner_knuckle.dae" />
        </geometry>
        <material name="">
          <color rgba="1 1 1 1" />
        </material>
      </visual>
      <collision>
        <origin xyz="0 0 0" rpy="0 0 0" />
        <geometry>
          <mesh filename="package://dh_description/meshes/ag95/inner_knuckle.dae" />
        </geometry>
      </collision>
      <inertial>
        <origin xyz="-0.0014206 0.023192 -3.3876E-10" rpy="0 0 0" />
        <mass value="0.011317" />
        <inertia
          ixx="6.694E-06" ixy="1.0721E-07" ixz="2.7063E-15"
          iyy="3.1292E-06" iyz="-4.9646E-14"
          izz="3.7346E-06" />
      </inertial>
    </link>

  </xacro:macro>

</robot>
