<?xml version="1.0" encoding="utf-8"?>
<!-- This URDF was automatically created by SolidWorks to URDF Exporter! Originally created by Stephen Brawner (brawner@gmail.com)
     Commit Version: 1.5.1-0-g916b5db  Build Version: 1.5.7152.31018
     For more information, please see http://wiki.ros.org/sw_urdf_exporter -->
<robot
  name="dh_description">
  <link
    name="base_link">
    <inertial>
      <origin
        xyz="-1.9172E-05 4.6267E-05 0.054522"
        rpy="0 0 0" />
      <mass
        value="0.3499" />
      <inertia
        ixx="0.00050797"
        ixy="6.5338E-08"
        ixz="-7.1191E-08"
        iyy="0.00038427"
        iyz="3.8152E-07"
        izz="0.00016523" />
    </inertial>
    <visual>
      <origin
        xyz="0 0 0"
        rpy="0 0 0" />
      <geometry>
        <mesh
          filename="package://dh_description/meshes/base_link.STL" />
      </geometry>
      <material
        name="">
        <color
          rgba="0.79216 0.81961 0.93333 1" />
      </material>
    </visual>
    <collision>
      <origin
        xyz="0 0 0"
        rpy="0 0 0" />
      <geometry>
        <mesh
          filename="package://dh_description/meshes/base_link.STL" />
      </geometry>
    </collision>
  </link>
  <link
    name="right_outer_finger">
    <inertial>
      <origin
        xyz="0.056202 0.03372 -6.3379E-11"
        rpy="0 0 0" />
      <mass
        value="0.0067722" />
      <inertia
        ixx="1.3438E-06"
        ixy="-4.6858E-07"
        ixz="4.7977E-15"
        iyy="6.4835E-07"
        iyz="1.7311E-15"
        izz="1.4005E-06" />
    </inertial>
    <visual>
      <origin
        xyz="0 0 0"
        rpy="0 0 0" />
      <geometry>
        <mesh
          filename="package://dh_description/meshes/right_outer_finger.STL" />
      </geometry>
      <material
        name="">
        <color
          rgba="0.79216 0.81961 0.93333 1" />
      </material>
    </visual>
    <collision>
      <origin
        xyz="0 0 0"
        rpy="0 0 0" />
      <geometry>
        <mesh
          filename="package://dh_description/meshes/right_outer_finger.STL" />
      </geometry>
    </collision>
  </link>
  <joint
    name="right_outer_finger_joint"
    type="revolute">
    <origin
      xyz="0 -0.02121 0.069339"
      rpy="1.5708 0.32949 1.5708" />
    <parent
      link="base_link" />
    <child
      link="right_outer_finger" />
    <axis
      xyz="0 0 1" />
    <limit
      lower="-1"
      upper="1"
      effort="90"
      velocity="5" />
  </joint>
  <link
    name="right_outer_knuckle">
    <inertial>
      <origin
        xyz="0.020694 -0.01587 -3.2261E-11"
        rpy="0 0 0" />
      <mass
        value="0.0079313" />
      <inertia
        ixx="1.6657E-06"
        ixy="1.1368E-06"
        ixz="-2.0382E-15"
        iyy="2.63E-06"
        iyz="3.0915E-15"
        izz="2.5842E-06" />
    </inertial>
    <visual>
      <origin
        xyz="0 0 0"
        rpy="0 0 0" />
      <geometry>
        <mesh
          filename="package://dh_description/meshes/right_outer_knuckle.STL" />
      </geometry>
      <material
        name="">
        <color
          rgba="0.82353 0.82353 0.82353 1" />
      </material>
    </visual>
    <collision>
      <origin
        xyz="0 0 0"
        rpy="0 0 0" />
      <geometry>
        <mesh
          filename="package://dh_description/meshes/right_outer_knuckle.STL" />
      </geometry>
    </collision>
  </link>
  <joint
    name="right_outer_knuckle_joint"
    type="revolute">
    <origin
      xyz="0.060381 0.045726 0"
      rpy="0 0 2.5809" />
    <parent
      link="right_outer_finger" />
    <child
      link="right_outer_knuckle" />
    <axis
      xyz="0 0 1" />
    <limit
      lower="-1"
      upper="1"
      effort="90"
      velocity="5" />
    <mimic
      joint="right_outer_finger_joint"
      multiplier="1"
      offset="0" />
  </joint>
  <link
    name="right_inner_finger">
    <inertial>
      <origin
        xyz="0.0065415 -0.00088999 -3.4935E-11"
        rpy="0 0 0" />
      <mass
        value="0.0063242" />
      <inertia
        ixx="4.5852E-07"
        ixy="1.4329E-07"
        ixz="-1.8883E-16"
        iyy="5.9203E-07"
        iyz="-2.1194E-13"
        izz="5.3236E-07" />
    </inertial>
    <visual>
      <origin
        xyz="0 0 0"
        rpy="0 0 0" />
      <geometry>
        <mesh
          filename="package://dh_description/meshes/right_inner_finger.STL" />
      </geometry>
      <material
        name="">
        <color
          rgba="0.79216 0.81961 0.93333 1" />
      </material>
    </visual>
    <collision>
      <origin
        xyz="0 0 0"
        rpy="0 0 0" />
      <geometry>
        <mesh
          filename="package://dh_description/meshes/right_inner_finger.STL" />
      </geometry>
    </collision>
  </link>
  <joint
    name="right_inner_finger_joint"
    type="revolute">
    <origin
      xyz="0.060704 -0.027852 0"
      rpy="0 0 -2.2514" />
    <parent
      link="right_outer_knuckle" />
    <child
      link="right_inner_finger" />
    <axis
      xyz="0 0 1" />
    <limit
      lower="-1"
      upper="1"
      effort="90"
      velocity="5" />
    <mimic
      joint="right_outer_finger_joint"
      multiplier="1"
      offset="0" />
  </joint>
  <link
    name="right_inner_finger_pad">
    <inertial>
      <origin
        xyz="2.7756E-17 -0.022596 0.0031612"
        rpy="0 0 0" />
      <mass
        value="0.013257" />
      <inertia
        ixx="6.5031E-06"
        ixy="-1.0656E-21"
        ixz="4.2343E-22"
        iyy="5.2255E-07"
        iyz="-1.4497E-07"
        izz="6.9079E-06" />
    </inertial>
    <visual>
      <origin
        xyz="0 0 0"
        rpy="0 0 0" />
      <geometry>
        <mesh
          filename="package://dh_description/meshes/right_inner_finger_pad.STL" />
      </geometry>
      <material
        name="">
        <color
          rgba="0.75294 0.75294 0.75294 1" />
      </material>
    </visual>
    <collision>
      <origin
        xyz="0 0 0"
        rpy="0 0 0" />
      <geometry>
        <mesh
          filename="package://dh_description/meshes/right_inner_finger_pad.STL" />
      </geometry>
    </collision>
  </link>
  <joint
    name="right_inner_finger_pad_joint"
    type="fixed">
    <origin
      xyz="-0.0005 0.07265 0"
      rpy="3.1416 -1.5708 0" />
    <parent
      link="right_inner_finger" />
    <child
      link="right_inner_finger_pad" />
    <axis
      xyz="0 0 0" />
  </joint>
  <link
    name="left_outer_finger">
    <inertial>
      <origin
        xyz="-0.024754 0.0060365 6.3379E-11"
        rpy="0 0 0" />
      <mass
        value="0.0067722" />
      <inertia
        ixx="6.2937E-07"
        ixy="4.5388E-07"
        ixz="4.8532E-15"
        iyy="1.3628E-06"
        iyz="1.569E-15"
        izz="1.4005E-06" />
    </inertial>
    <visual>
      <origin
        xyz="0 0 0"
        rpy="0 0 0" />
      <geometry>
        <mesh
          filename="package://dh_description/meshes/left_outer_finger.STL" />
      </geometry>
      <material
        name="">
        <color
          rgba="0.79216 0.81961 0.93333 1" />
      </material>
    </visual>
    <collision>
      <origin
        xyz="0 0 0"
        rpy="0 0 0" />
      <geometry>
        <mesh
          filename="package://dh_description/meshes/left_outer_finger.STL" />
      </geometry>
    </collision>
  </link>
  <joint
    name="left_outer_finger_joint"
    type="revolute">
    <origin
      xyz="0 -0.02121 0.069339"
      rpy="1.5708 0.32949 1.5708" />
    <parent
      link="base_link" />
    <child
      link="left_outer_finger" />
    <axis
      xyz="0 0 1" />
    <limit
      lower="-1"
      upper="1"
      effort="90"
      velocity="5" />
    <mimic
      joint="right_outer_finger_joint"
      multiplier="1"
      offset="0" />
  </joint>
  <link
    name="left_outer_knuckle">
    <inertial>
      <origin
        xyz="0.020694 -0.01587 -3.226E-11"
        rpy="0 0 0" />
      <mass
        value="0.0079313" />
      <inertia
        ixx="1.6657E-06"
        ixy="1.1368E-06"
        ixz="-2.0382E-15"
        iyy="2.63E-06"
        iyz="3.0915E-15"
        izz="2.5842E-06" />
    </inertial>
    <visual>
      <origin
        xyz="0 0 0"
        rpy="0 0 0" />
      <geometry>
        <mesh
          filename="package://dh_description/meshes/left_outer_knuckle.STL" />
      </geometry>
      <material
        name="">
        <color
          rgba="0.82353 0.82353 0.82353 1" />
      </material>
    </visual>
    <collision>
      <origin
        xyz="0 0 0"
        rpy="0 0 0" />
      <geometry>
        <mesh
          filename="package://dh_description/meshes/left_outer_knuckle.STL" />
      </geometry>
    </collision>
  </link>
  <joint
    name="left_outer_knuckle_joint"
    type="revolute">
    <origin
      xyz="-0.035409 0.01297 0"
      rpy="-3.1416 0 1.2197" />
    <parent
      link="left_outer_finger" />
    <child
      link="left_outer_knuckle" />
    <axis
      xyz="0 0 1" />
    <limit
      lower="-1"
      upper="1"
      effort="90"
      velocity="5" />
    <mimic
      joint="right_outer_finger_joint"
      multiplier="1"
      offset="0" />
  </joint>
  <link
    name="left_inner_finger">
    <inertial>
      <origin
        xyz="0.0065415 -0.00088999 -3.4935E-11"
        rpy="0 0 0" />
      <mass
        value="0.0063242" />
      <inertia
        ixx="4.5852E-07"
        ixy="1.4329E-07"
        ixz="-1.8883E-16"
        iyy="5.9203E-07"
        iyz="-2.1194E-13"
        izz="5.3236E-07" />
    </inertial>
    <visual>
      <origin
        xyz="0 0 0"
        rpy="0 0 0" />
      <geometry>
        <mesh
          filename="package://dh_description/meshes/left_inner_finger.STL" />
      </geometry>
      <material
        name="">
        <color
          rgba="0.79216 0.81961 0.93333 1" />
      </material>
    </visual>
    <collision>
      <origin
        xyz="0 0 0"
        rpy="0 0 0" />
      <geometry>
        <mesh
          filename="package://dh_description/meshes/left_inner_finger.STL" />
      </geometry>
    </collision>
  </link>
  <joint
    name="left_inner_finger_joint"
    type="revolute">
    <origin
      xyz="0.060704 -0.027852 0"
      rpy="0 0 -2.2514" />
    <parent
      link="left_outer_knuckle" />
    <child
      link="left_inner_finger" />
    <axis
      xyz="0 0 1" />
    <limit
      lower="-1"
      upper="1"
      effort="90"
      velocity="5" />
    <mimic
      joint="right_outer_finger_joint"
      multiplier="1"
      offset="0" />
  </joint>
  <link
    name="left_inner_finger_pad">
    <inertial>
      <origin
        xyz="1.3878E-17 0.022596 0.0031612"
        rpy="0 0 0" />
      <mass
        value="0.013257" />
      <inertia
        ixx="6.5031E-06"
        ixy="-1.3119E-21"
        ixz="-4.7535E-22"
        iyy="5.2255E-07"
        iyz="1.4497E-07"
        izz="6.9079E-06" />
    </inertial>
    <visual>
      <origin
        xyz="0 0 0"
        rpy="0 0 0" />
      <geometry>
        <mesh
          filename="package://dh_description/meshes/left_inner_finger_pad.STL" />
      </geometry>
      <material
        name="">
        <color
          rgba="0.75294 0.75294 0.75294 1" />
      </material>
    </visual>
    <collision>
      <origin
        xyz="0 0 0"
        rpy="0 0 0" />
      <geometry>
        <mesh
          filename="package://dh_description/meshes/left_inner_finger_pad.STL" />
      </geometry>
    </collision>
  </link>
  <joint
    name="left_inner_finger_pad_joint"
    type="fixed">
    <origin
      xyz="-0.0005 0.07265 0"
      rpy="3.1416 1.5708 0" />
    <parent
      link="left_inner_finger" />
    <child
      link="left_inner_finger_pad" />
    <axis
      xyz="0 0 0" />
  </joint>
  <link
    name="right_inner_knuckle">
    <inertial>
      <origin
        xyz="-0.0014206 0.023192 -3.3876E-10"
        rpy="0 0 0" />
      <mass
        value="0.011317" />
      <inertia
        ixx="6.694E-06"
        ixy="1.0721E-07"
        ixz="2.7063E-15"
        iyy="3.1292E-06"
        iyz="-4.9646E-14"
        izz="3.7346E-06" />
    </inertial>
    <visual>
      <origin
        xyz="0 0 0"
        rpy="0 0 0" />
      <geometry>
        <mesh
          filename="package://dh_description/meshes/right_inner_knuckle.STL" />
      </geometry>
      <material
        name="">
        <color
          rgba="1 1 1 1" />
      </material>
    </visual>
    <collision>
      <origin
        xyz="0 0 0"
        rpy="0 0 0" />
      <geometry>
        <mesh
          filename="package://dh_description/meshes/right_inner_knuckle.STL" />
      </geometry>
    </collision>
  </link>
  <joint
    name="right_inner_knuckle_joint"
    type="revolute">
    <origin
      xyz="0 0.016 0.10586"
      rpy="1.5708 0.34572 1.5708" />
    <parent
      link="base_link" />
    <child
      link="right_inner_knuckle" />
    <axis
      xyz="0 0 1" />
    <limit
      lower="-1"
      upper="1"
      effort="90"
      velocity="5" />
    <mimic
      joint="right_outer_finger_joint"
      multiplier="1"
      offset="0" />
  </joint>
  <link
    name="left_inner_knuckle">
    <inertial>
      <origin
        xyz="-0.0014206 0.023192 -3.3876E-10"
        rpy="0 0 0" />
      <mass
        value="0.011317" />
      <inertia
        ixx="6.694E-06"
        ixy="1.0721E-07"
        ixz="2.7063E-15"
        iyy="3.1292E-06"
        iyz="-4.9646E-14"
        izz="3.7346E-06" />
    </inertial>
    <visual>
      <origin
        xyz="0 0 0"
        rpy="0 0 0" />
      <geometry>
        <mesh
          filename="package://dh_description/meshes/left_inner_knuckle.STL" />
      </geometry>
      <material
        name="">
        <color
          rgba="1 1 1 1" />
      </material>
    </visual>
    <collision>
      <origin
        xyz="0 0 0"
        rpy="0 0 0" />
      <geometry>
        <mesh
          filename="package://dh_description/meshes/left_inner_knuckle.STL" />
      </geometry>
    </collision>
  </link>
  <joint
    name="left_inner_knucke_joint"
    type="revolute">
    <origin
      xyz="0 -0.0158 0.10586"
      rpy="1.5708 0.34572 -1.5708" />
    <parent
      link="base_link" />
    <child
      link="left_inner_knuckle" />
    <axis
      xyz="0 0 1" />
    <limit
      lower="-1"
      upper="1"
      effort="90"
      velocity="5" />
    <mimic
      joint="right_outer_finger_joint"
      multiplier="1"
      offset="0" />
  </joint>
  <link
    name="right_bottom_knuckle">
    <inertial>
      <origin
        xyz="0.019421 0.0012759 5.0395E-09"
        rpy="0 0 0" />
      <mass
        value="0.0039541" />
      <inertia
        ixx="1.1534E-06"
        ixy="-2.1521E-09"
        ixz="-1.124E-13"
        iyy="1.7667E-06"
        iyz="-9.3728E-15"
        izz="6.8389E-07" />
    </inertial>
    <visual>
      <origin
        xyz="0 0 0"
        rpy="0 0 0" />
      <geometry>
        <mesh
          filename="package://dh_description/meshes/right_bottom_knuckle.STL" />
      </geometry>
      <material
        name="">
        <color
          rgba="0.79216 0.81961 0.93333 1" />
      </material>
    </visual>
    <collision>
      <origin
        xyz="0 0 0"
        rpy="0 0 0" />
      <geometry>
        <mesh
          filename="package://dh_description/meshes/right_bottom_knuckle.STL" />
      </geometry>
    </collision>
  </link>
  <joint
    name="right_bottom_knuckle_joint"
    type="revolute">
    <origin
      xyz="0 0.016 0.10586"
      rpy="-1.5708 0.35302 1.5708" />
    <parent
      link="base_link" />
    <child
      link="right_bottom_knuckle" />
    <axis
      xyz="0 0 1" />
    <limit
      lower="-1"
      upper="1"
      effort="90"
      velocity="5" />
    <mimic
      joint="right_outer_finger_joint"
      multiplier="1"
      offset="0" />
  </joint>
  <link
    name="left_bottom_knuckle">
    <inertial>
      <origin
        xyz="0.019421 0.0012759 5.0395E-09"
        rpy="0 0 0" />
      <mass
        value="0.0039541" />
      <inertia
        ixx="1.1534E-06"
        ixy="-2.1521E-09"
        ixz="-1.124E-13"
        iyy="1.7667E-06"
        iyz="-9.3728E-15"
        izz="6.8389E-07" />
    </inertial>
    <visual>
      <origin
        xyz="0 0 0"
        rpy="0 0 0" />
      <geometry>
        <mesh
          filename="package://dh_description/meshes/left_bottom_knuckle.STL" />
      </geometry>
      <material
        name="">
        <color
          rgba="0.79216 0.81961 0.93333 1" />
      </material>
    </visual>
    <collision>
      <origin
        xyz="0 0 0"
        rpy="0 0 0" />
      <geometry>
        <mesh
          filename="package://dh_description/meshes/left_bottom_knuckle.STL" />
      </geometry>
    </collision>
  </link>
  <joint
    name="left_bottom_knuckle_joint"
    type="revolute">
    <origin
      xyz="0 -0.0158 0.10586"
      rpy="-1.5708 0.35302 -1.5708" />
    <parent
      link="base_link" />
    <child
      link="left_bottom_knuckle" />
    <axis
      xyz="0 0 1" />
    <limit
      lower="-1"
      upper="1"
      effort="90"
      velocity="5" />
    <mimic
      joint="right_outer_finger_joint"
      multiplier="1"
      offset="0" />
  </joint>
</robot>
