<?xml version="1.0" ?>
<!-- =================================================================================== -->
<!-- |    This document was autogenerated by xacro from ./src/dh_description/urdf/ag95_gripper.urdf.xacro | -->
<!-- |    EDITING THIS FILE BY HAND IS NOT RECOMMENDED                                 | -->
<!-- =================================================================================== -->
<robot name="ag95" xmlns:xacro="http://www.ros.org/wiki/xacro">
  <link name="ag95_base_link">
    <visual>
      <origin rpy="0 0 0" xyz="0 0 0"/>
      <geometry>
        <mesh filename="package://dh_description/meshes/ag95/base_link.dae"/>
      </geometry>
      <material name="">
        <color rgba="0.79216 0.81961 0.93333 1"/>
      </material>
    </visual>
    <collision>
      <origin rpy="0 0 0" xyz="0 0 0"/>
      <geometry>
        <mesh filename="package://dh_description/meshes/ag95/base_link.dae"/>
      </geometry>
    </collision>
    <inertial>
      <origin rpy="0 0 0" xyz="-1.9172E-05 4.6267E-05 0.054522"/>
      <mass value="0.3499"/>
      <inertia ixx="0.00050797" ixy="6.5338E-08" ixz="-7.1191E-08" iyy="0.00038427" iyz="3.8152E-07" izz="0.00016523"/>
    </inertial>
  </link>
  <joint name="ag95_finger_joint" type="prismatic">
    <origin rpy="0 0 0" xyz="0. 0. 0.085"/>
    <parent link="ag95_base_link"/>
    <child link="ag95_finger"/>
    <axis xyz="0 0 1"/>
    <limit effort="90.0" lower="-0.03" upper="0.0" velocity="0.03"/>
  </joint>
  <link name="ag95_finger">
    <visual>
      <origin rpy="0 0 0" xyz="0 0 0"/>
      <geometry>
        <mesh filename="package://dh_description/meshes/ag95/finger.dae"/>
      </geometry>
      <material name="">
        <color rgba="1 1 1 1"/>
      </material>
    </visual>
    <collision>
      <origin rpy="0 0 0" xyz="0 0 0"/>
      <geometry>
        <mesh filename="package://dh_description/meshes/ag95/finger.dae"/>
      </geometry>
    </collision>
    <inertial>
      <origin rpy="0 0 0" xyz="3.9135E-14 1.9462E-12 3.5194E-14"/>
      <mass value="0.0066216"/>
      <inertia ixx="1.4212E-06" ixy="-4.5344E-18" ixz="2.1335E-18" iyy="1.8936E-07" iyz="-2.1705E-19" izz="1.4719E-06"/>
    </inertial>
  </link>
  <joint name="ag95_left_outer_finger_joint" type="revolute">
    <origin rpy="-1.57079632679 0 1.57079632679" xyz="0. 0.02141 0."/>
    <parent link="ag95_finger"/>
    <child link="ag95_left_outer_finger"/>
    <axis xyz="0 0 1"/>
    <limit effort="90.0" lower="-0.5236" upper="-0.22689" velocity="1.0"/>
    <mimic joint="ag95_finger_joint" multiplier="9.89033333333" offset="-0.22689"/>
  </joint>
  <link name="ag95_left_outer_finger">
    <visual>
      <origin rpy="0 0 0" xyz="0 0 0"/>
      <geometry>
        <mesh filename="package://dh_description/meshes/ag95/outer_finger.dae"/>
      </geometry>
      <material name="">
        <color rgba="0.79216 0.81961 0.93333 1"/>
      </material>
    </visual>
    <collision>
      <origin rpy="0 0 0" xyz="0 0 0"/>
      <geometry>
        <mesh filename="package://dh_description/meshes/ag95/outer_finger.dae"/>
      </geometry>
    </collision>
    <inertial>
      <origin rpy="0 0 0" xyz="0.056202 0.03372 -6.3379E-11"/>
      <mass value="0.0067722"/>
      <inertia ixx="1.3438E-06" ixy="-4.6858E-07" ixz="4.7977E-15" iyy="6.4835E-07" iyz="1.7311E-15" izz="1.4005E-06"/>
    </inertial>
  </link>
  <joint name="ag95_left_bottom_knuckle_joint" type="revolute">
    <origin rpy="-1.57079632679 0 1.57079632679" xyz="0 0.016 0.10586"/>
    <parent link="ag95_base_link"/>
    <child link="ag95_left_bottom_knuckle"/>
    <axis xyz="0 0 1"/>
    <limit effort="90.0" lower="0.008727" upper="0.637045" velocity="1.0"/>
    <mimic joint="ag95_finger_joint" multiplier="-20.9439333333" offset="0.008727"/>
  </joint>
  <link name="ag95_left_bottom_knuckle">
    <visual>
      <origin rpy="0 0 0" xyz="0 0 0"/>
      <geometry>
        <mesh filename="package://dh_description/meshes/ag95/bottom_knuckle.dae"/>
      </geometry>
      <material name="">
        <color rgba="0.79216 0.81961 0.93333 1"/>
      </material>
    </visual>
    <collision>
      <origin rpy="0 0 0" xyz="0 0 0"/>
      <geometry>
        <mesh filename="package://dh_description/meshes/ag95/bottom_knuckle.dae"/>
      </geometry>
    </collision>
    <inertial>
      <origin rpy="0 0 0" xyz="0.019421 0.0012759 5.0395E-09"/>
      <mass value="0.0039541"/>
      <inertia ixx="1.1534E-06" ixy="-2.1521E-09" ixz="-1.124E-13" iyy="1.7667E-06" iyz="-9.3728E-15" izz="6.8389E-07"/>
    </inertial>
  </link>
  <joint name="ag95_left_inner_knuckle_joint" type="revolute">
    <origin rpy="1.57079632679 0 -1.57079632679" xyz="0 0.016 0.10586"/>
    <parent link="ag95_base_link"/>
    <child link="ag95_left_inner_knuckle"/>
    <axis xyz="0 0 1"/>
    <limit effort="90.0" lower="1.42244" upper="2.33525" velocity="1.0"/>
    <mimic joint="ag95_finger_joint" multiplier="-30.427" offset="1.42244"/>
  </joint>
  <link name="ag95_left_inner_knuckle">
    <visual>
      <origin rpy="0 0 0" xyz="0 0 0"/>
      <geometry>
        <mesh filename="package://dh_description/meshes/ag95/inner_knuckle.dae"/>
      </geometry>
      <material name="">
        <color rgba="1 1 1 1"/>
      </material>
    </visual>
    <collision>
      <origin rpy="0 0 0" xyz="0 0 0"/>
      <geometry>
        <mesh filename="package://dh_description/meshes/ag95/inner_knuckle.dae"/>
      </geometry>
    </collision>
    <inertial>
      <origin rpy="0 0 0" xyz="-0.0014206 0.023192 -3.3876E-10"/>
      <mass value="0.011317"/>
      <inertia ixx="6.694E-06" ixy="1.0721E-07" ixz="2.7063E-15" iyy="3.1292E-06" iyz="-4.9646E-14" izz="3.7346E-06"/>
    </inertial>
  </link>
  <joint name="ag95_left_outer_knuckle_joint" type="revolute">
    <origin rpy="0 0 0" xyz="0.035409 -0.01297 0"/>
    <parent link="ag95_left_outer_finger"/>
    <child link="ag95_left_outer_knuckle"/>
    <axis xyz="0 0 1"/>
    <limit effort="90.0" lower="-1.93926" upper="-0.72431" velocity="1.0"/>
    <mimic joint="ag95_finger_joint" multiplier="-40.4983333333" offset="-1.93926"/>
  </joint>
  <link name="ag95_left_outer_knuckle">
    <visual>
      <origin rpy="0 0 0" xyz="0 0 0"/>
      <geometry>
        <mesh filename="package://dh_description/meshes/ag95/outer_knuckle.dae"/>
      </geometry>
      <material name="">
        <color rgba="0.82353 0.82353 0.82353 1"/>
      </material>
    </visual>
    <collision>
      <origin rpy="0 0 0" xyz="0 0 0"/>
      <geometry>
        <mesh filename="package://dh_description/meshes/ag95/outer_knuckle.dae"/>
      </geometry>
    </collision>
    <inertial>
      <origin rpy="0 0 0" xyz="0.020694 -0.01587 -3.2261E-11"/>
      <mass value="0.0079313"/>
      <inertia ixx="1.6657E-06" ixy="1.1368E-06" ixz="-2.0382E-15" iyy="2.63E-06" iyz="3.0915E-15" izz="2.5842E-06"/>
    </inertial>
  </link>
  <joint name="ag95_left_inner_finger_joint" type="revolute">
    <origin rpy="0 0 0" xyz="0.055 -0.0005 0"/>
    <parent link="ag95_left_inner_knuckle"/>
    <child link="ag95_left_inner_finger"/>
    <axis xyz="0 0 1"/>
    <limit effort="90.0" lower="-0.764453673205" upper="0.148356326795" velocity="1.0"/>
    <mimic joint="ag95_finger_joint" multiplier="30.427" offset="0.148356326795"/>
  </joint>
  <link name="ag95_left_inner_finger">
    <visual>
      <origin rpy="0 0 0" xyz="0 0 0"/>
      <geometry>
        <mesh filename="package://dh_description/meshes/ag95/inner_finger.dae"/>
      </geometry>
      <material name="">
        <color rgba="0.79216 0.81961 0.93333 1"/>
      </material>
    </visual>
    <collision>
      <origin rpy="0 0 0" xyz="0 0 0"/>
      <geometry>
        <mesh filename="package://dh_description/meshes/ag95/inner_finger.dae"/>
      </geometry>
    </collision>
    <inertial>
      <origin rpy="0 0 0" xyz="0.0065415 -0.00088999 -3.4935E-11"/>
      <mass value="0.0063242"/>
      <inertia ixx="4.5852E-07" ixy="1.4329E-07" ixz="-1.8883E-16" iyy="5.9203E-07" iyz="-2.1194E-13" izz="5.3236E-07"/>
    </inertial>
  </link>
  <joint name="ag95_left_inner_finger_pad_joint" type="fixed">
    <origin rpy="1.57079632679 0 0" xyz="0.0104 -0.0005 0"/>
    <parent link="ag95_left_inner_finger"/>
    <child link="ag95_left_inner_finger_pad"/>
  </joint>
  <link name="ag95_left_inner_finger_pad">
    <visual>
      <origin rpy="0 0 0" xyz="0 0 0"/>
      <geometry>
        <mesh filename="package://dh_description/meshes/ag95/inner_finger_pad.dae"/>
      </geometry>
      <material name="">
        <color rgba="0.75294 0.75294 0.75294 1"/>
      </material>
    </visual>
    <collision>
      <origin rpy="0 0 0" xyz="0 0 0"/>
      <geometry>
        <mesh filename="package://dh_description/meshes/ag95/inner_finger_pad.dae"/>
      </geometry>
    </collision>
    <inertial>
      <origin rpy="0 0 0" xyz="2.7756E-17 -0.022596 0.0031612"/>
      <mass value="0.013257"/>
      <inertia ixx="6.5031E-06" ixy="-1.0656E-21" ixz="4.2343E-22" iyy="5.2255E-07" iyz="-1.4497E-07" izz="6.9079E-06"/>
    </inertial>
  </link>
  <joint name="ag95_right_outer_finger_joint" type="revolute">
    <origin rpy="-1.57079632679 0 -1.57079632679" xyz="0. -0.02141 0."/>
    <parent link="ag95_finger"/>
    <child link="ag95_right_outer_finger"/>
    <axis xyz="0 0 1"/>
    <limit effort="90.0" lower="-0.5236" upper="-0.22689" velocity="1.0"/>
    <mimic joint="ag95_finger_joint" multiplier="9.89033333333" offset="-0.22689"/>
  </joint>
  <link name="ag95_right_outer_finger">
    <visual>
      <origin rpy="0 0 0" xyz="0 0 0"/>
      <geometry>
        <mesh filename="package://dh_description/meshes/ag95/outer_finger.dae"/>
      </geometry>
      <material name="">
        <color rgba="0.79216 0.81961 0.93333 1"/>
      </material>
    </visual>
    <collision>
      <origin rpy="0 0 0" xyz="0 0 0"/>
      <geometry>
        <mesh filename="package://dh_description/meshes/ag95/outer_finger.dae"/>
      </geometry>
    </collision>
    <inertial>
      <origin rpy="0 0 0" xyz="0.056202 0.03372 -6.3379E-11"/>
      <mass value="0.0067722"/>
      <inertia ixx="1.3438E-06" ixy="-4.6858E-07" ixz="4.7977E-15" iyy="6.4835E-07" iyz="1.7311E-15" izz="1.4005E-06"/>
    </inertial>
  </link>
  <joint name="ag95_right_bottom_knuckle_joint" type="revolute">
    <origin rpy="-1.57079632679 0 -1.57079632679" xyz="0 -0.016 0.10586"/>
    <parent link="ag95_base_link"/>
    <child link="ag95_right_bottom_knuckle"/>
    <axis xyz="0 0 1"/>
    <limit effort="90.0" lower="0.008727" upper="0.637045" velocity="1.0"/>
    <mimic joint="ag95_finger_joint" multiplier="-20.9439333333" offset="0.008727"/>
  </joint>
  <link name="ag95_right_bottom_knuckle">
    <visual>
      <origin rpy="0 0 0" xyz="0 0 0"/>
      <geometry>
        <mesh filename="package://dh_description/meshes/ag95/bottom_knuckle.dae"/>
      </geometry>
      <material name="">
        <color rgba="0.79216 0.81961 0.93333 1"/>
      </material>
    </visual>
    <collision>
      <origin rpy="0 0 0" xyz="0 0 0"/>
      <geometry>
        <mesh filename="package://dh_description/meshes/ag95/bottom_knuckle.dae"/>
      </geometry>
    </collision>
    <inertial>
      <origin rpy="0 0 0" xyz="0.019421 0.0012759 5.0395E-09"/>
      <mass value="0.0039541"/>
      <inertia ixx="1.1534E-06" ixy="-2.1521E-09" ixz="-1.124E-13" iyy="1.7667E-06" iyz="-9.3728E-15" izz="6.8389E-07"/>
    </inertial>
  </link>
  <joint name="ag95_right_inner_knuckle_joint" type="revolute">
    <origin rpy="1.57079632679 0 1.57079632679" xyz="0 -0.016 0.10586"/>
    <parent link="ag95_base_link"/>
    <child link="ag95_right_inner_knuckle"/>
    <axis xyz="0 0 1"/>
    <limit effort="90.0" lower="1.42244" upper="2.33525" velocity="1.0"/>
    <mimic joint="ag95_finger_joint" multiplier="-30.427" offset="1.42244"/>
  </joint>
  <link name="ag95_right_inner_knuckle">
    <visual>
      <origin rpy="0 0 0" xyz="0 0 0"/>
      <geometry>
        <mesh filename="package://dh_description/meshes/ag95/inner_knuckle.dae"/>
      </geometry>
      <material name="">
        <color rgba="1 1 1 1"/>
      </material>
    </visual>
    <collision>
      <origin rpy="0 0 0" xyz="0 0 0"/>
      <geometry>
        <mesh filename="package://dh_description/meshes/ag95/inner_knuckle.dae"/>
      </geometry>
    </collision>
    <inertial>
      <origin rpy="0 0 0" xyz="-0.0014206 0.023192 -3.3876E-10"/>
      <mass value="0.011317"/>
      <inertia ixx="6.694E-06" ixy="1.0721E-07" ixz="2.7063E-15" iyy="3.1292E-06" iyz="-4.9646E-14" izz="3.7346E-06"/>
    </inertial>
  </link>
  <joint name="ag95_right_outer_knuckle_joint" type="revolute">
    <origin rpy="0 0 0" xyz="0.035409 -0.01297 0"/>
    <parent link="ag95_right_outer_finger"/>
    <child link="ag95_right_outer_knuckle"/>
    <axis xyz="0 0 1"/>
    <limit effort="90.0" lower="-1.93926" upper="-0.72431" velocity="1.0"/>
    <mimic joint="ag95_finger_joint" multiplier="-40.4983333333" offset="-1.93926"/>
  </joint>
  <link name="ag95_right_outer_knuckle">
    <visual>
      <origin rpy="0 0 0" xyz="0 0 0"/>
      <geometry>
        <mesh filename="package://dh_description/meshes/ag95/outer_knuckle.dae"/>
      </geometry>
      <material name="">
        <color rgba="0.82353 0.82353 0.82353 1"/>
      </material>
    </visual>
    <collision>
      <origin rpy="0 0 0" xyz="0 0 0"/>
      <geometry>
        <mesh filename="package://dh_description/meshes/ag95/outer_knuckle.dae"/>
      </geometry>
    </collision>
    <inertial>
      <origin rpy="0 0 0" xyz="0.020694 -0.01587 -3.2261E-11"/>
      <mass value="0.0079313"/>
      <inertia ixx="1.6657E-06" ixy="1.1368E-06" ixz="-2.0382E-15" iyy="2.63E-06" iyz="3.0915E-15" izz="2.5842E-06"/>
    </inertial>
  </link>
  <joint name="ag95_right_inner_finger_joint" type="revolute">
    <origin rpy="0 0 0" xyz="0.055 -0.0005 0"/>
    <parent link="ag95_right_inner_knuckle"/>
    <child link="ag95_right_inner_finger"/>
    <axis xyz="0 0 1"/>
    <limit effort="90.0" lower="-0.764453673205" upper="0.148356326795" velocity="1.0"/>
    <mimic joint="ag95_finger_joint" multiplier="30.427" offset="0.148356326795"/>
  </joint>
  <link name="ag95_right_inner_finger">
    <visual>
      <origin rpy="0 0 0" xyz="0 0 0"/>
      <geometry>
        <mesh filename="package://dh_description/meshes/ag95/inner_finger.dae"/>
      </geometry>
      <material name="">
        <color rgba="0.79216 0.81961 0.93333 1"/>
      </material>
    </visual>
    <collision>
      <origin rpy="0 0 0" xyz="0 0 0"/>
      <geometry>
        <mesh filename="package://dh_description/meshes/ag95/inner_finger.dae"/>
      </geometry>
    </collision>
    <inertial>
      <origin rpy="0 0 0" xyz="0.0065415 -0.00088999 -3.4935E-11"/>
      <mass value="0.0063242"/>
      <inertia ixx="4.5852E-07" ixy="1.4329E-07" ixz="-1.8883E-16" iyy="5.9203E-07" iyz="-2.1194E-13" izz="5.3236E-07"/>
    </inertial>
  </link>
  <joint name="ag95_right_inner_finger_pad_joint" type="fixed">
    <origin rpy="1.57079632679 0 0" xyz="0.0104 -0.0005 0"/>
    <parent link="ag95_right_inner_finger"/>
    <child link="ag95_right_inner_finger_pad"/>
  </joint>
  <link name="ag95_right_inner_finger_pad">
    <visual>
      <origin rpy="0 0 0" xyz="0 0 0"/>
      <geometry>
        <mesh filename="package://dh_description/meshes/ag95/inner_finger_pad.dae"/>
      </geometry>
      <material name="">
        <color rgba="0.75294 0.75294 0.75294 1"/>
      </material>
    </visual>
    <collision>
      <origin rpy="0 0 0" xyz="0 0 0"/>
      <geometry>
        <mesh filename="package://dh_description/meshes/ag95/inner_finger_pad.dae"/>
      </geometry>
    </collision>
    <inertial>
      <origin rpy="0 0 0" xyz="2.7756E-17 -0.022596 0.0031612"/>
      <mass value="0.013257"/>
      <inertia ixx="6.5031E-06" ixy="-1.0656E-21" ixz="4.2343E-22" iyy="5.2255E-07" iyz="-1.4497E-07" izz="6.9079E-06"/>
    </inertial>
  </link>
  <transmission name="ag95_finger_trans">
    <type>transmission_interface/SimpleTransmission</type>
    <joint name="ag95_finger_joint">
      <hardwareInterface>hardware_interface/PositionJointInterface</hardwareInterface>
    </joint>
    <actuator name="ag95_finger_motor">
      <mechanicalReduction>-3333.33333333</mechanicalReduction>
    </actuator>
  </transmission>
  <gazebo reference="ag95_base_link">
    <material>Gazebo/Black</material>
  </gazebo>
  <gazebo reference="ag95_finger">
    <material>Gazebo/Grey</material>
  </gazebo>
  <gazebo reference="ag95_left_outer_finger">
    <material>Gazebo/Grey</material>
  </gazebo>
  <gazebo reference="ag95_left_bottom_knuckle">
    <material>Gazebo/Black</material>
  </gazebo>
  <gazebo reference="ag95_left_inner_knuckle">
    <material>Gazebo/Black</material>
  </gazebo>
  <gazebo reference="ag95_left_outer_knuckle">
    <material>Gazebo/Black</material>
  </gazebo>
  <gazebo reference="ag95_left_inner_finger">
    <material>Gazebo/Grey</material>
  </gazebo>
  <gazebo reference="ag95_left_inner_finger_pad">
    <material>Gazebo/Grey</material>
  </gazebo>
  <gazebo reference="ag95_right_outer_finger">
    <material>Gazebo/Grey</material>
  </gazebo>
  <gazebo reference="ag95_right_bottom_knuckle">
    <material>Gazebo/Black</material>
  </gazebo>
  <gazebo reference="ag95_right_inner_knuckle">
    <material>Gazebo/Black</material>
  </gazebo>
  <gazebo reference="ag95_right_outer_knuckle">
    <material>Gazebo/Black</material>
  </gazebo>
  <gazebo reference="ag95_right_inner_finger">
    <material>Gazebo/Grey</material>
  </gazebo>
  <gazebo reference="ag95_right_inner_finger_pad">
    <material>Gazebo/Grey</material>
  </gazebo>
  <!-- ros_control plugin -->
  <gazebo>
    <plugin filename="libgazebo_ros_control.so" name="gazebo_ros_control">
      <robotNamespace>/dh_ag95</robotNamespace>
      <legacyModeNS>false</legacyModeNS>
    </plugin>
  </gazebo>
</robot>
