<sdf version="1.4">
  <model name="closed_chain">

    <link name="bottom_pad">
      <self_collide>1</self_collide>
      <pose>0 0 0 0 0 0</pose>
      <visual name="bottom_pad_visual">
        <geometry>
        <box>
          <size>1.0 1.0 0.1</size>
        </box>
        </geometry>
        <material>
          <script>
            <uri>file://media/materials/scripts/gazebo.material</uri>
            <name>Gazebo/Red</name>
          </script>
        </material>
      </visual>
      <collision name="bottom_pad_collision">
        <geometry>
          <box>
            <size>1.0 1.0 0.1</size>
          </box>
        </geometry>
      </collision>
    </link>

    <joint name="bottom_left_pad_joint" type="revolute">
      <pose>0 0.5 0 0 0 0</pose>
      <parent>bottom_pad</parent>
      <child>left_pad</child>
      <axis>
        <xyz>1 0 0</xyz>
      </axis>
    </joint>

    <link name="left_pad">
      <self_collide>1</self_collide>
      <pose>0. 0.5 0.5 -1.5707963268 0. 0.</pose>
      <visual name="left_pad_visual">
        <geometry>
          <box>
            <size>1.0 1.0 0.1</size>
          </box>
        </geometry>
        <material>
          <script>
            <uri>file://media/materials/scripts/gazebo.material</uri>
            <name>Gazebo/Green</name>
          </script>
        </material>
      </visual>
      <collision name="left_pad_collision">
        <geometry>
          <box>
            <size>1.0 1.0 0.1</size>
          </box>
        </geometry>
      </collision>
    </link>

    <joint name="bottom_right_pad_joint" type="revolute">
      <pose>0 -0.5 0 0 0 0</pose>
      <parent>bottom_pad</parent>
      <child>right_pad</child>
      <axis>
        <xyz>1 0 0</xyz>
      </axis>
    </joint>

    <link name="right_pad">
      <self_collide>1</self_collide>
      <pose>0. -0.5 0.5 1.5707963268 0. 0.</pose>
      <visual name="right_pad_visual">
        <geometry>
          <box>
            <size>1.0 1.0 0.1</size>
          </box>
        </geometry>
        <material>
          <script>
            <uri>file://media/materials/scripts/gazebo.material</uri>
            <name>Gazebo/Blue</name>
          </script>
        </material>
      </visual>
      <collision name="right_pad_collision">
        <geometry>
          <box>
            <size>1.0 1.0 0.1</size>
          </box>
        </geometry>
      </collision>
    </link>

    <joint name="top_left_pad_joint" type="revolute">
      <pose>0 -0.5 0 0 0 0</pose>
      <parent>top_pad</parent>
      <child>left_pad</child>
      <axis>
        <xyz>1 0 0</xyz>
      </axis>
    </joint>

    <link name="top_pad">
      <self_collide>1</self_collide>
      <pose>0. 0. 1.0 3.141592 0 0</pose>
      <visual name="top_pad_visual">
        <geometry>
          <box>
            <size>1.0 1.0 0.1</size>
          </box>
        </geometry>
        <material>
          <script>
            <uri>file://media/materials/scripts/gazebo.material</uri>
            <name>Gazebo/Yellow</name>
          </script>
        </material>
      </visual>
      <collision name="top_pad_collision">
        <geometry>
          <box>
            <size>1.0 1.0 0.1</size>
          </box>
        </geometry>
      </collision>
    </link>

    <joint name="top_right_pad_joint" type="revolute">
      <pose>0 0.5 0 0 0 0</pose>
      <parent>top_pad</parent>
      <child>right_pad</child>
      <axis>
        <xyz>1 0 0</xyz>
      </axis>
    </joint>

    <static>0</static>
  </model>
</sdf>
